Workbook

Sheet final_plots
A1: Params | B1: RH [%] | C1: PC | D1: CaCl_1 | E1: CaCl_12 | F1: ZnN_5 | G1: ZnN_15 | H1: LiCl_10 | I1: p_20 | J1: p_tr_40 LiCl_10 | K1: p_tr_90 LiCl_10
B3: RH [%] | C3: dm [g/g] | D3: dm [g/g] | E3: dm [g/g] | F3: dm [g/g] | G3: dm [g/g] | H3: dm [g/g]
B4: 0 | C4: 0 | D4: 0 | E4: 0 | F4: 0 | G4: 0 | H4: 0 | I4: 0 | J4: 0 | K4: 0
B5: 5 | E5: 0.012081547 | F5: 0.0089237538 | G5: 0.0042071457 | H5: 0.048975385 | I5: =B5/100*$K$19 -> 1.16965 | J5: 4.4710313 | K5: 62.51431
B6: 10 | C6: 0.017494775 | D6: 0.046421774 | E6: 0.029011023 | F6: 0.026563732 | G6: 0.015014051 | H6: 0.09460509 | I6: =B6/100*$K$19 -> 2.3393 | J6: 8.5548377 | K6: 109.39149
B7: 15 | E7: 0.067080016 | F7: 0.074025651 | G7: 0.073962264 | H7: 0.24958179 | I7: =B7/100*$K$19 -> 3.50895 | J7: 12.504219 | K7: 151.7511
B8: 20 | C8: 0.027877031 | D8: 0.06914612 | E8: 0.10026281 | F8: 0.09807828 | G8: 0.093520674 | H8: 0.30639861 | I8: =B8/100*$K$19 -> 4.6786 | J8: 16.368762 | K8: 191.42016
B9: 25 | E9: 0.13229741 | F9: 0.12003486 | G9: 0.13289442 | H9: 0.36993667 | I9: =B9/100*$K$19 -> 5.84825 | J9: 20.171421 | K9: 229.20153
B10: 30 | C10: 0.037248028 | D10: 0.098395844 | E10: 0.15813176 | F10: 0.14074627 | G10: 0.15656363 | H10: 0.43347473 | I10: =B10/100*$K$19 -> 7.0179 | J10: 23.92548 | K10: 265.54367
B11: 35 | E11: 0.22470147 | F11: 0.1618935 | G11: 0.17798475 | H11: 0.50917075 | I11: =B11/100*$K$19 -> 8.18755 | J11: 27.639599 | K11: 300.73102
B12: 40 | C12: 0.046147104 | D12: 0.12554199 | E12: 0.29016126 | F12: 0.18299921 | G12: 0.2006102 | H12: 0.58128211 | I12: =B12/100*$K$19 -> 9.3572 | J12: 31.319867 | K12: 334.9591
B13: 45 | E13: 0.35407736 | F13: 0.20690657 | G13: 0.22530711 | H13: 0.6497192 | I13: =B13/100*$K$19 -> 10.52685 | J13: 34.970792 | K13: 368.37
B14: 50 | C14: 0.055888896 | D14: 0.165882 | E14: 0.42285415 | F14: 0.23344955 | G14: 0.25252509 | H14: 0.72849205 | I14: =B14/100*$K$19 -> 11.6965 | J14: 38.595845 | K14: 401.07134
A17: Xa | C17: 0.022543195 | D17: 0.056522358 | E17: 0.059032449 | F17: 0.062646933 | G17: 0.059021456 | H17: 0.20656348 | J17: pA | K17: 12.282
A18: Xc | C18: 0.0087095276 | D18: 0.022953085 | E18: 0.0076824759 | F18: 0.0057890535 | G18: 0.001764111 | H18: 0.028474749 | J18: pC | K18: 42.47
A19: DeltaX | C19: 0.013833667 | D19: 0.033569273 | E19: 0.051349974 | F19: 0.056857879 | G19: 0.057257345 | H19: 0.17808873 | J19: p0_20 | K19: 23.393
A20: qst | C20: 48.890915 | D20: 48.863978 | E20: 48.670023 | F20: 48.710723 | G20: 48.596859 | H20: 48.75483 | J20: p0_40 | K20: 73.849
A21: Qu | C21: 37.543194 | D21: 91.053468 | E21: 138.72908 | F21: 153.73791 | G21: 154.45613 | H21: 481.96979 | J21: p0_90 | K21: 701.82
A22: W0_20 | C22: 0.1237728 | D22: 0.94233965 | E22: 2.6433731 | F22: 0.32345214 | G22: 0.31098906 | H22: 1.1238206
A23: E_20 | C23: 2286.7762 | D23: 509.3896 | E23: 733.84588 | F23: 3360.9188 | G23: 3578.74 | H23: 3115.4801
A24: n_20 | C24: 0.74554322 | D24: 0.46688017 | E24: 0.72159069 | F24: 1.5063053 | G24: 1.9077944 | H24: 1.3017092

Sheet Valori output_1_20
B1: RH [%] | C1: SrB_50 | D1: LiCl_50 | E1: MgCl_50 | F1: CaCl_50 | G1: MgN_50 | H1: ZnN_50 | I1: AlS_50 | J1: CuS_50 | K1: KAlS_50 | L1: MgS_50 | M1: PC | N1: KC_50 | O1: - | P1: - | Q1: - | R1: - | S1: - | T1: - | U1: - | V1: - | W1: - | X1: - | Y1: -
C2: ='Valori input_1_20'!B$1 -> S01 | D2: ='Valori input_1_20'!C$1 -> S02 | E2: ='Valori input_1_20'!D$1 -> S03 | F2: ='Valori input_1_20'!E$1 -> S04 | G2: ='Valori input_1_20'!F$1 -> S05 | H2: ='Valori input_1_20'!G$1 -> S06 | I2: ='Valori input_1_20'!H$1 -> S07 | J2: ='Valori input_1_20'!I$1 -> S08 | ... Y2: ='Valori input_1_20'!X$1 -> S23
B3: RH [%] | C3: dm [g/g] | D3: dm [g/g] | E3: dm [g/g] | F3: dm [g/g] | G3: dm [g/g] | H3: dm [g/g] | I3: dm [g/g] | J3: dm [g/g] | K3: dm [g/g] | L3: dm [g/g] | M3: dm [g/g] | N3: dm [g/g] | O3: dm [g/g] | P3: dm [g/g] | Q3: dm [g/g] | R3: dm [g/g] | S3: dm [g/g] | T3: dm [g/g] | U3: dm [g/g] | V3: dm [g/g] | W3: dm [g/g] | X3: dm [g/g] | Y3: dm [g/g]
B4: 0 | C4: ='Valori input_1_20'!B5*'Valori input_1_20'!$B$18 -> 0 | D4: ='Valori input_1_20'!C5*'Valori input_1_20'!$B$18 -> 0 | E4: ='Valori input_1_20'!D5*'Valori input_1_20'!$B$18 -> 0 | F4: ='Valori input_1_20'!E5*'Valori input_1_20'!$B$18 -> 0 | G4: ='Valori input_1_20'!F5*'Valori input_1_20'!$B$18 -> 0 | H4: ='Valori input_1_20'!G5*'Valori input_1_20'!$B$18 -> 0 | I4: ='Valori input_1_20'!H5*'Valori input_1_20'!$B$18 -> 0 | J4: ='Valori input_1_20'!I5*'Valori input_1_20'!$B$18 -> 0 | ... Y4: ='Valori input_1_20'!X5*'Valori input_1_20'!$B$18 -> 0
B5: 10 | C5: ='Valori input_1_20'!B6*'Valori input_1_20'!$B$18 -> 0.049218512 | D5: ='Valori input_1_20'!C6*'Valori input_1_20'!$B$18 -> 0.060460022 | E5: ='Valori input_1_20'!D6*'Valori input_1_20'!$B$18 -> 0.037255933 | F5: ='Valori input_1_20'!E6*'Valori input_1_20'!$B$18 -> 0.046421774 | G5: ='Valori input_1_20'!F6*'Valori input_1_20'!$B$18 -> 0.030415196 | H5: ='Valori input_1_20'!G6*'Valori input_1_20'!$B$18 -> 0.017626614 | I5: ='Valori input_1_20'!H6*'Valori input_1_20'!$B$18 -> 0.010122423 | J5: ='Valori input_1_20'!I6*'Valori input_1_20'!$B$18 -> 0.0047356315 | ... Y5: ='Valori input_1_20'!X6*'Valori input_1_20'!$B$18 -> 0
B6: 20 | C6: ='Valori input_1_20'!B7*'Valori input_1_20'!$B$18 -> 0.09699131 | D6: ='Valori input_1_20'!C7*'Valori input_1_20'!$B$18 -> 0.12235388 | E6: ='Valori input_1_20'!D7*'Valori input_1_20'!$B$18 -> 0.065001908 | F6: ='Valori input_1_20'!E7*'Valori input_1_20'!$B$18 -> 0.06914612 | G6: ='Valori input_1_20'!F7*'Valori input_1_20'!$B$18 -> 0.051605406 | H6: ='Valori input_1_20'!G7*'Valori input_1_20'!$B$18 -> 0.069347898 | I6: ='Valori input_1_20'!H7*'Valori input_1_20'!$B$18 -> 0.017383009 | J6: ='Valori input_1_20'!I7*'Valori input_1_20'!$B$18 -> 0.0075619766 | ... Y6: ='Valori input_1_20'!X7*'Valori input_1_20'!$B$18 -> 0
B7: 30 | C7: ='Valori input_1_20'!B8*'Valori input_1_20'!$B$18 -> 0.11801841 | D7: ='Valori input_1_20'!C8*'Valori input_1_20'!$B$18 -> 0.18247536 | E7: ='Valori input_1_20'!D8*'Valori input_1_20'!$B$18 -> 0.093232664 | F7: ='Valori input_1_20'!E8*'Valori input_1_20'!$B$18 -> 0.098395844 | G7: ='Valori input_1_20'!F8*'Valori input_1_20'!$B$18 -> 0.074574618 | H7: ='Valori input_1_20'!G8*'Valori input_1_20'!$B$18 -> 0.095642999 | I7: ='Valori input_1_20'!H8*'Valori input_1_20'!$B$18 -> 0.023654318 | J7: ='Valori input_1_20'!I8*'Valori input_1_20'!$B$18 -> 0.0098471068 | ... Y7: ='Valori input_1_20'!X8*'Valori input_1_20'!$B$18 -> 0
B8: 40 | C8: ='Valori input_1_20'!B9*'Valori input_1_20'!$B$18 -> 0.13331084 | D8: ='Valori input_1_20'!C9*'Valori input_1_20'!$B$18 -> 0.25956388 | E8: ='Valori input_1_20'!D9*'Valori input_1_20'!$B$18 -> 0.12639375 | F8: ='Valori input_1_20'!E9*'Valori input_1_20'!$B$18 -> 0.12554199 | G8: ='Valori input_1_20'!F9*'Valori input_1_20'!$B$18 -> 0.094803592 | H8: ='Valori input_1_20'!G9*'Valori input_1_20'!$B$18 -> 0.12305528 | I8: ='Valori input_1_20'!H9*'Valori input_1_20'!$B$18 -> 0.029907962 | J8: ='Valori input_1_20'!I9*'Valori input_1_20'!$B$18 -> 0.012057068 | ... Y8: ='Valori input_1_20'!X9*'Valori input_1_20'!$B$18 -> 0
B9: 50 | C9: ='Valori input_1_20'!B10*'Valori input_1_20'!$B$18 -> 0.15629769 | D9: ='Valori input_1_20'!C10*'Valori input_1_20'!$B$18 -> 0.32912476 | E9: ='Valori input_1_20'!D10*'Valori input_1_20'!$B$18 -> 0.1712102 | F9: ='Valori input_1_20'!E10*'Valori input_1_20'!$B$18 -> 0.165882 | G9: ='Valori input_1_20'!F10*'Valori input_1_20'!$B$18 -> 0.11595076 | H9: ='Valori input_1_20'!G10*'Valori input_1_20'!$B$18 -> 0.1550811 | I9: ='Valori input_1_20'!H10*'Valori input_1_20'!$B$18 -> 0.040666349 | J9: ='Valori input_1_20'!I10*'Valori input_1_20'!$B$18 -> 0.015244223 | ... Y9: ='Valori input_1_20'!X10*'Valori input_1_20'!$B$18 -> 0
B10: 60 | C10: ='Valori input_1_20'!B11*'Valori input_1_20'!$B$18 -> 0.22511365 | D10: ='Valori input_1_20'!C11*'Valori input_1_20'!$B$18 -> 0.41646918 | E10: ='Valori input_1_20'!D11*'Valori input_1_20'!$B$18 -> 0.26637167 | F10: ='Valori input_1_20'!E11*'Valori input_1_20'!$B$18 -> 0.32855855 | G10: ='Valori input_1_20'!F11*'Valori input_1_20'!$B$18 -> 0.14170325 | H10: ='Valori input_1_20'!G11*'Valori input_1_20'!$B$18 -> 0.19823734 | I10: ='Valori input_1_20'!H11*'Valori input_1_20'!$B$18 -> 0.050841769 | J10: ='Valori input_1_20'!I11*'Valori input_1_20'!$B$18 -> 0.01943864 | ... Y10: ='Valori input_1_20'!X11*'Valori input_1_20'!$B$18 -> 0
B11: 70 | C11: ='Valori input_1_20'!B12*'Valori input_1_20'!$B$18 -> 0.26649318 | D11: ='Valori input_1_20'!C12*'Valori input_1_20'!$B$18 -> 0.53912178 | E11: ='Valori input_1_20'!D12*'Valori input_1_20'!$B$18 -> 0.35832534 | F11: ='Valori input_1_20'!E12*'Valori input_1_20'!$B$18 -> 0.42572373 | G11: ='Valori input_1_20'!F12*'Valori input_1_20'!$B$18 -> 0.18325156 | H11: ='Valori input_1_20'!G12*'Valori input_1_20'!$B$18 -> 0.26770937 | I11: ='Valori input_1_20'!H12*'Valori input_1_20'!$B$18 -> 0.11403183 | J11: ='Valori input_1_20'!I12*'Valori input_1_20'!$B$18 -> 0.0324278 | ... Y11: ='Valori input_1_20'!X12*'Valori input_1_20'!$B$18 -> 0
B12: 80 | C12: ='Valori input_1_20'!B13*'Valori input_1_20'!$B$18 -> 0.33026521 | D12: ='Valori input_1_20'!C13*'Valori input_1_20'!$B$18 -> 0.74418003 | E12: ='Valori input_1_20'!D13*'Valori input_1_20'!$B$18 -> 0.48149065 | F12: ='Valori input_1_20'!E13*'Valori input_1_20'!$B$18 -> 0.56133999 | G12: ='Valori input_1_20'!F13*'Valori input_1_20'!$B$18 -> 0.26616166 | H12: ='Valori input_1_20'!G13*'Valori input_1_20'!$B$18 -> 0.39202665 | I12: ='Valori input_1_20'!H13*'Valori input_1_20'!$B$18 -> 0.20213048 | J12: ='Valori input_1_20'!I13*'Valori input_1_20'!$B$18 -> 0.072567915 | ... Y12: ='Valori input_1_20'!X13*'Valori input_1_20'!$B$18 -> 0
B13: 90 | C13: ='Valori input_1_20'!B14*'Valori input_1_20'!$B$18 -> 0.46666024 | D13: ='Valori input_1_20'!C14*'Valori input_1_20'!$B$18 -> 1.0937768 | E13: ='Valori input_1_20'!D14*'Valori input_1_20'!$B$18 -> 0.67504203 | F13: ='Valori input_1_20'!E14*'Valori input_1_20'!$B$18 -> 0.78899844 | G13: ='Valori input_1_20'!F14*'Valori input_1_20'!$B$18 -> 0.40591375 | H13: ='Valori input_1_20'!G14*'Valori input_1_20'!$B$18 -> 0.61316617 | I13: ='Valori input_1_20'!H14*'Valori input_1_20'!$B$18 -> 0.23145547 | J13: ='Valori input_1_20'!I14*'Valori input_1_20'!$B$18 -> 0.089931897 | ... Y13: ='Valori input_1_20'!X14*'Valori input_1_20'!$B$18 -> 0
A16: Xa | C16: 0.072473782 | D16: 0.088502313 | E16: 0.049251389 | F16: 0.056522358 | G16: 0.04100528 | H16: 0.040885223 | I16: 0.013066722 | J16: 0.0060277733 | K16: 0.024328001 | L16: 0.026910765 | M16: 0.022543195 | N16: 0.020960959 | P16: pA | Q16: 12.282 | R16: mbar
A17: Xc | C17: 0.01381089 | D17: 0.019609811 | E17: 0.016537226 | F17: 0.022953085 | G17: 0.012872283 | H17: 0.0024178391 | I17: 0.004167264 | J17: 0.0024687955 | K17: 0.0096374531 | L17: 0.012403682 | M17: 0.0087095276 | N17: 0.0079844981 | P17: pC | Q17: 42.47 | R17: mbar
A18: deltax | C18: 0.058662893 | D18: 0.068892502 | E18: 0.032714163 | F18: 0.033569273 | G18: 0.028132997 | H18: 0.038467384 | I18: 0.0088994585 | J18: 0.0035589778 | K18: 0.014690547 | L18: 0.014507083 | M18: 0.013833667 | N18: 0.01297646
A19: qst | C19: 48.879809 | D19: 48.788197 | E19: 48.829663 | F19: 48.863978 | G19: 48.855609 | H19: 48.666652 | I19: 48.845801 | J19: 48.891071 | K19: 48.89742 | L19: 48.918078 | M19: 48.890915 | N19: 48.882161
A20: Qu | C20: 159.16908 | D20: 186.57458 | E20: 88.671748 | F20: 91.053468 | G20: 76.295014 | H20: 103.91778 | I20: 24.129957 | J20: 9.6587419 | K20: 39.873987 | L20: 39.392651 | M20: 37.543194 | N20: 35.210515
A21: W0_20 | C21: 0.17695781 | D21: 0.84873356 | E21: 1.0016901 | F21: 0.94233965 | G21: 0.25932586 | H21: 0.20016221 | I21: 0.10993387 | J21: 0.039633264 | K21: 0.12532304 | L21: 0.13634721 | M21: 0.1237728 | N21: 0.13379579
A22: E_20 | C22: 4980.8748 | D22: 1805.6421 | E22: 559.01523 | F22: 509.3896 | G22: 2212.089 | H22: 3567.9033 | I22: 1638.6129 | J22: 1768.7172 | K22: 2421.5752 | L22: 2232.2727 | M22: 2286.7762 | N22: 1944.5442
A23: n_20 | C23: 1.7640319 | D23: 0.85830821 | E23: 0.51948182 | F23: 0.46688017 | G23: 0.81912591 | H23: 1.7183243 | I23: 0.72181683 | J23: 0.6519277 | K23: 0.75247088 | L23: 0.65572545 | M23: 0.74554322 | N23: 0.7043374

Sheet Valori output_2_20
B1: RH [%] | C1: SrB_2 | D1: LiCl_2 | E1: MgCl_2 | F1: CaCl_2 | G1: MgN_2 | H1: ZnN_2 | I1: AlS_2 | J1: CuS_2 | K1: KAlS_2 | L1: MgS_2 | M1: KC_2 | N1: SrB_50_bis | O1: CaCl_50_bis | P1: MgN_50_bis | Q1: ZnN_50_bis | R1: AlS_50_bis | S1: MgS_50_bis | T1: - | U1: - | V1: - | W1: - | X1: - | Y1: -
C2: ='Valori input_2_20'!B$1 -> S07 | D2: ='Valori input_2_20'!C$1 -> S09 | E2: ='Valori input_2_20'!D$1 -> S10 | F2: ='Valori input_2_20'!E$1 -> S11 | G2: ='Valori input_2_20'!F$1 -> S13 | H2: ='Valori input_2_20'!G$1 -> S15 | I2: ='Valori input_2_20'!H$1 -> S17 | J2: ='Valori input_2_20'!I$1 -> S19 | ... Y2: ='Valori input_2_20'!X$1 -> S23
B3: RH [%] | C3: dm [g] | D3: dm [g] | E3: dm [g] | F3: dm [g] | G3: dm [g] | H3: dm [g] | I3: dm [g] | J3: dm [g] | K3: dm [g] | L3: dm [g] | M3: dm [g] | N3: dm [g] | O3: dm [g] | P3: dm [g] | Q3: dm [g] | R3: dm [g] | S3: dm [g] | T3: dm [g] | U3: dm [g] | V3: dm [g] | W3: dm [g] | X3: dm [g] | Y3: dm [g]
B4: 0 | C4: ='Valori input_2_20'!B5*'Valori input_2_20'!$B$18 -> 0 | D4: ='Valori input_2_20'!C5*'Valori input_2_20'!$B$18 -> 0 | E4: ='Valori input_2_20'!D5*'Valori input_2_20'!$B$18 -> 0 | F4: ='Valori input_2_20'!E5*'Valori input_2_20'!$B$18 -> 0 | G4: ='Valori input_2_20'!F5*'Valori input_2_20'!$B$18 -> 0 | H4: ='Valori input_2_20'!G5*'Valori input_2_20'!$B$18 -> 0 | I4: ='Valori input_2_20'!H5*'Valori input_2_20'!$B$18 -> 0 | J4: ='Valori input_2_20'!I5*'Valori input_2_20'!$B$18 -> 0 | ... Y4: ='Valori input_2_20'!X5*'Valori input_2_20'!$B$18 -> 0
B5: 10 | C5: ='Valori input_2_20'!B6*'Valori input_2_20'!$B$18 -> 0.027402005 | D5: ='Valori input_2_20'!C6*'Valori input_2_20'!$B$18 -> 0.025269907 | E5: ='Valori input_2_20'!D6*'Valori input_2_20'!$B$18 -> 0.016411542 | F5: ='Valori input_2_20'!E6*'Valori input_2_20'!$B$18 -> 0.031235907 | G5: ='Valori input_2_20'!F6*'Valori input_2_20'!$B$18 -> 0.018795065 | H5: ='Valori input_2_20'!G6*'Valori input_2_20'!$B$18 -> 0.012689377 | I5: ='Valori input_2_20'!H6*'Valori input_2_20'!$B$18 -> 0.0057417582 | J5: ='Valori input_2_20'!I6*'Valori input_2_20'!$B$18 -> 0.0017386791 | ... Y5: ='Valori input_2_20'!X6*'Valori input_2_20'!$B$18 -> 0
B6: 20 | C6: ='Valori input_2_20'!B7*'Valori input_2_20'!$B$18 -> 0.049735643 | D6: ='Valori input_2_20'!C7*'Valori input_2_20'!$B$18 -> 0.039884965 | E6: ='Valori input_2_20'!D7*'Valori input_2_20'!$B$18 -> 0.042714767 | F6: ='Valori input_2_20'!E7*'Valori input_2_20'!$B$18 -> 0.077377703 | G6: ='Valori input_2_20'!F7*'Valori input_2_20'!$B$18 -> 0.035642279 | H6: ='Valori input_2_20'!G7*'Valori input_2_20'!$B$18 -> 0.033798808 | I6: ='Valori input_2_20'!H7*'Valori input_2_20'!$B$18 -> 0.012637363 | J6: ='Valori input_2_20'!I7*'Valori input_2_20'!$B$18 -> 0.0050862852 | ... Y6: ='Valori input_2_20'!X7*'Valori input_2_20'!$B$18 -> 0
B7: 30 | C7: ='Valori input_2_20'!B8*'Valori input_2_20'!$B$18 -> 0.067183227 | D7: ='Valori input_2_20'!C8*'Valori input_2_20'!$B$18 -> 0.053368535 | E7: ='Valori input_2_20'!D8*'Valori input_2_20'!$B$18 -> 0.086190434 | F7: ='Valori input_2_20'!E8*'Valori input_2_20'!$B$18 -> 0.13023664 | G7: ='Valori input_2_20'!F8*'Valori input_2_20'!$B$18 -> 0.053275467 | H7: ='Valori input_2_20'!G8*'Valori input_2_20'!$B$18 -> 0.050994693 | I7: ='Valori input_2_20'!H8*'Valori input_2_20'!$B$18 -> 0.020576923 | J7: ='Valori input_2_20'!I8*'Valori input_2_20'!$B$18 -> 0.0085895939 | ... Y7: ='Valori input_2_20'!X8*'Valori input_2_20'!$B$18 -> 0
B8: 40 | C8: ='Valori input_2_20'!B9*'Valori input_2_20'!$B$18 -> 0.080255242 | D8: ='Valori input_2_20'!C9*'Valori input_2_20'!$B$18 -> 0.066404224 | E8: ='Valori input_2_20'!D9*'Valori input_2_20'!$B$18 -> 0.12657775 | F8: ='Valori input_2_20'!E9*'Valori input_2_20'!$B$18 -> 0.20084973 | G8: ='Valori input_2_20'!F9*'Valori input_2_20'!$B$18 -> 0.066910433 | H8: ='Valori input_2_20'!G9*'Valori input_2_20'!$B$18 -> 0.067805153 | I8: ='Valori input_2_20'!H9*'Valori input_2_20'!$B$18 -> 0.02706044 | J8: ='Valori input_2_20'!I9*'Valori input_2_20'!$B$18 -> 0.011599844 | ... Y8: ='Valori input_2_20'!X9*'Valori input_2_20'!$B$18 -> 0
B9: 50 | C9: ='Valori input_2_20'!B10*'Valori input_2_20'!$B$18 -> 0.10030994 | D9: ='Valori input_2_20'!C10*'Valori input_2_20'!$B$18 -> 0.09016548 | E9: ='Valori input_2_20'!D10*'Valori input_2_20'!$B$18 -> 0.19966879 | F9: ='Valori input_2_20'!E10*'Valori input_2_20'!$B$18 -> 0.3137832 | G9: ='Valori input_2_20'!F10*'Valori input_2_20'!$B$18 -> 0.082322387 | H9: ='Valori input_2_20'!G10*'Valori input_2_20'!$B$18 -> 0.089566842 | I9: ='Valori input_2_20'!H10*'Valori input_2_20'!$B$18 -> 0.04717033 | J9: ='Valori input_2_20'!I10*'Valori input_2_20'!$B$18 -> 0.01793175 | ... Y9: ='Valori input_2_20'!X10*'Valori input_2_20'!$B$18 -> 0
B10: 60 | C10: ='Valori input_2_20'!B11*'Valori input_2_20'!$B$18 -> 0.12971741 | D10: ='Valori input_2_20'!C11*'Valori input_2_20'!$B$18 -> 0.11833483 | E10: ='Valori input_2_20'!D11*'Valori input_2_20'!$B$18 -> 0.32342673 | F10: ='Valori input_2_20'!E11*'Valori input_2_20'!$B$18 -> 0.52773492 | G10: ='Valori input_2_20'!F11*'Valori input_2_20'!$B$18 -> 0.10022896 | H10: ='Valori input_2_20'!G11*'Valori input_2_20'!$B$18 -> 0.11865161 | I10: ='Valori input_2_20'!H11*'Valori input_2_20'!$B$18 -> 0.057692308 | J10: ='Valori input_2_20'!I11*'Valori input_2_20'!$B$18 -> 0.023822499 | ... Y10: ='Valori input_2_20'!X11*'Valori input_2_20'!$B$18 -> 0
B11: 70 | C11: ='Valori input_2_20'!B12*'Valori input_2_20'!$B$18 -> 0.1620784 | D11: ='Valori input_2_20'!C12*'Valori input_2_20'!$B$18 -> 0.15607468 | E11: ='Valori input_2_20'!D12*'Valori input_2_20'!$B$18 -> 0.42951989 | F11: ='Valori input_2_20'!E12*'Valori input_2_20'!$B$18 -> 0.67475256 | G11: ='Valori input_2_20'!F12*'Valori input_2_20'!$B$18 -> 0.13334245 | H11: ='Valori input_2_20'!G12*'Valori input_2_20'!$B$18 -> 0.16771917 | I11: ='Valori input_2_20'!H12*'Valori input_2_20'!$B$18 -> 0.091071429 | J11: ='Valori input_2_20'!I12*'Valori input_2_20'!$B$18 -> 0.034306475 | ... Y11: ='Valori input_2_20'!X12*'Valori input_2_20'!$B$18 -> 0
B12: 80 | C12: ='Valori input_2_20'!B13*'Valori input_2_20'!$B$18 -> 0.20758432 | D12: ='Valori input_2_20'!C13*'Valori input_2_20'!$B$18 -> 0.2219603 | E12: ='Valori input_2_20'!D13*'Valori input_2_20'!$B$18 -> 0.59106914 | F12: ='Valori input_2_20'!E13*'Valori input_2_20'!$B$18 -> 0.91395884 | G12: ='Valori input_2_20'!F13*'Valori input_2_20'!$B$18 -> 0.20011619 | H12: ='Valori input_2_20'!G13*'Valori input_2_20'!$B$18 -> 0.26345282 | I12: ='Valori input_2_20'!H13*'Valori input_2_20'!$B$18 -> 0.14700549 | J12: ='Valori input_2_20'!I13*'Valori input_2_20'!$B$18 -> 0.066407162 | ... Y12: ='Valori input_2_20'!X13*'Valori input_2_20'!$B$18 -> 0
B13: 90 | C13: ='Valori input_2_20'!B14*'Valori input_2_20'!$B$18 -> 0.32435734 | D13: ='Valori input_2_20'!C14*'Valori input_2_20'!$B$18 -> 0.37591344 | E13: ='Valori input_2_20'!D14*'Valori input_2_20'!$B$18 -> 0.8587563 | F13: ='Valori input_2_20'!E14*'Valori input_2_20'!$B$18 -> 1.3139493 | G13: ='Valori input_2_20'!F14*'Valori input_2_20'!$B$18 -> 0.30099443 | H13: ='Valori input_2_20'!G14*'Valori input_2_20'!$B$18 -> 0.46200599 | I13: ='Valori input_2_20'!H14*'Valori input_2_20'!$B$18 -> 0.19431319 | J13: ='Valori input_2_20'!I14*'Valori input_2_20'!$B$18 -> 0.097054626 | ... Y13: ='Valori input_2_20'!X14*'Valori input_2_20'!$B$18 -> 0
A16: Xc | C16: 0.038635776 | D16: 0.031397379 | E16: 0.028313529 | F16: 0.049867126 | G16: 0.027470263 | H16: 0.022587937 | I16: 0.0078241901 | J16: 0.0029897471 | K16: 0.012140804 | L16: 0.01375885 | M16: 0.011677762 | V16: pA | W16: 12.282 | X16: mbar
A17: Xa | C17: 0.014643491 | D17: 0.013258069 | E17: 0.0040425302 | F17: 0.0099074279 | G17: 0.0069444065 | H17: 0.0038669313 | I17: 0.0016511352 | J17: 0.00056631807 | K17: 0.0025763017 | L17: 0.003848755 | M17: 0.0035626569 | V17: pC | W17: 42.47 | X17: mbar
A18: DeltaX | C18: 0.023992285 | D18: 0.01813931 | E18: 0.024270999 | F18: 0.039959698 | G18: 0.020525856 | H18: 0.018721006 | I18: 0.0061730549 | J18: 0.0024234291 | K18: 0.0095645024 | L18: 0.0099100947 | M18: 0.0081151055
A19: qst | C19: 48.88143 | D19: 48.869905 | E19: 48.68158 | F19: 48.722533 | G19: 48.830918 | H19: 48.758157 | I19: 48.734457 | J19: 48.721337 | K19: 48.773632 | L19: 48.828682 | M19: 48.886855
A20: Qu | C20: 65.100039 | D20: 49.207124 | E20: 65.587042 | F20: 108.07314 | G20: 55.636769 | H20: 50.668983 | I20: 16.699444 | J20: 6.5541329 | K20: 25.894839 | L20: 26.860775 | M20: 22.021759
A21: W0_20 | C21: 0.24679123 | D21: 0.53201046 | E21: 1.3781581 | F21: 4.2951876 | G21: 0.15761227 | H21: 0.18921431 | I21: 0.56218896 | J21: 0.16619252 | K21: 0.14614255 | L21: 0.11066416 | M21: 0.042598889
A22: E_20 | C22: 1950.1731 | D22: 455.35231 | E22: 639.27935 | F22: 263.87861 | G22: 2636.3883 | H22: 2223.3362 | I22: 288.22314 | J22: 428.48977 | K22: 1523.9014 | L22: 1867.2021 | M22: 3689.6146
A23: n_20 | C23: 0.7071077 | D23: 0.44685708 | E23: 0.6824497 | F23: 0.5199988 | G23: 0.97565139 | H23: 1.0158251 | I23: 0.5215627 | J23: 0.58222027 | K23: 0.8138396 | L23: 0.80134372 | M23: 1.0938221

Sheet Valori output_3_20
B1: RH [%] | C1: SrB_3 | D1: MgCl_4 | E1: LiCl_3 | F1: LiCl_4 | G1: ZnN_3 | H1: MgCl_5 | I1: LiCl_5 | J1: MgCl_6 | K1: LiCl_6 | L1: MgCl_7 | M1: ZnN_4 | N1: KAlS_3 | O1: KAlS_4 | P1: KAlS_5 | Q1: CaCl_3 | R1: KAlS_6 | S1: MgCl_8 | T1: KAlS_7 | U1: MgCl_9
C2: ='Valori input_3_20'!B$1 -> S01 | D2: ='Valori input_3_20'!C$1 -> S02 | E2: ='Valori input_3_20'!D$1 -> S03 | F2: ='Valori input_3_20'!E$1 -> S04 | G2: ='Valori input_3_20'!F$1 -> S05 | H2: ='Valori input_3_20'!G$1 -> S06 | I2: ='Valori input_3_20'!H$1 -> S07 | J2: ='Valori input_3_20'!I$1 -> S08 | ... U2: ='Valori input_3_20'!T$1 -> S19
B3: RH [%] | C3: dm [g] | D3: dm [g] | E3: dm [g] | F3: dm [g] | G3: dm [g] | H3: dm [g] | I3: dm [g] | J3: dm [g] | K3: dm [g] | L3: dm [g] | M3: dm [g] | N3: dm [g] | O3: dm [g] | P3: dm [g] | Q3: dm [g] | R3: dm [g] | S3: dm [g] | T3: dm [g] | U3: dm [g]
B4: 0 | C4: ='Valori input_3_20'!B5*'Valori input_3_20'!$B$19 -> 0 | D4: ='Valori input_3_20'!C5*'Valori input_3_20'!$B$19 -> 0 | E4: ='Valori input_3_20'!D5*'Valori input_3_20'!$B$19 -> 0 | F4: ='Valori input_3_20'!E5*'Valori input_3_20'!$B$19 -> 0 | G4: ='Valori input_3_20'!F5*'Valori input_3_20'!$B$19 -> 0 | H4: ='Valori input_3_20'!G5*'Valori input_3_20'!$B$19 -> 0 | I4: ='Valori input_3_20'!H5*'Valori input_3_20'!$B$19 -> 0 | J4: ='Valori input_3_20'!I5*'Valori input_3_20'!$B$19 -> 0 | ... U4: ='Valori input_3_20'!T5*'Valori input_3_20'!$B$19 -> 0
B5: 5 | C5: ='Valori input_3_20'!B6*'Valori input_3_20'!$B$19 -> 0.0054795818 | D5: ='Valori input_3_20'!C6*'Valori input_3_20'!$B$19 -> 0.0076991854 | E5: ='Valori input_3_20'!D6*'Valori input_3_20'!$B$19 -> 0.019138566 | F5: ='Valori input_3_20'!E6*'Valori input_3_20'!$B$19 -> 0.016889303 | G5: ='Valori input_3_20'!F6*'Valori input_3_20'!$B$19 -> 0.00028995713 | H5: ='Valori input_3_20'!G6*'Valori input_3_20'!$B$19 -> 0.005075594 | I5: ='Valori input_3_20'!H6*'Valori input_3_20'!$B$19 -> 0.010083564 | J5: ='Valori input_3_20'!I6*'Valori input_3_20'!$B$19 -> 0.0067627016 | ... U5: ='Valori input_3_20'!T6*'Valori input_3_20'!$B$19 -> 0.004767122
B6: 10 | C6: ='Valori input_3_20'!B7*'Valori input_3_20'!$B$19 -> 0.019202223 | D6: ='Valori input_3_20'!C7*'Valori input_3_20'!$B$19 -> 0.018627061 | E6: ='Valori input_3_20'!D7*'Valori input_3_20'!$B$19 -> 0.056023078 | F6: ='Valori input_3_20'!E7*'Valori input_3_20'!$B$19 -> 0.050234851 | G6: ='Valori input_3_20'!F7*'Valori input_3_20'!$B$19 -> 0.0056334528 | H6: ='Valori input_3_20'!G7*'Valori input_3_20'!$B$19 -> 0.014938805 | I6: ='Valori input_3_20'!H7*'Valori input_3_20'!$B$19 -> 0.042445177 | J6: ='Valori input_3_20'!I7*'Valori input_3_20'!$B$19 -> 0.018442163 | ... U6: ='Valori input_3_20'!T7*'Valori input_3_20'!$B$19 -> 0.01418481
B7: 15 | C7: ='Valori input_3_20'!B8*'Valori input_3_20'!$B$19 -> 0.039494047 | D7: ='Valori input_3_20'!C8*'Valori input_3_20'!$B$19 -> 0.028064773 | E7: ='Valori input_3_20'!D8*'Valori input_3_20'!$B$19 -> 0.10229782 | F7: ='Valori input_3_20'!E8*'Valori input_3_20'!$B$19 -> 0.094456844 | G7: ='Valori input_3_20'!F8*'Valori input_3_20'!$B$19 -> 0.012737402 | H7: ='Valori input_3_20'!G8*'Valori input_3_20'!$B$19 -> 0.024028078 | I7: ='Valori input_3_20'!H8*'Valori input_3_20'!$B$19 -> 0.077824881 | J7: ='Valori input_3_20'!I8*'Valori input_3_20'!$B$19 -> 0.028914 | ... U7: ='Valori input_3_20'!T8*'Valori input_3_20'!$B$19 -> 0.024523288
B8: 20 | C8: ='Valori input_3_20'!B9*'Valori input_3_20'!$B$19 -> 0.056106497 | D8: ='Valori input_3_20'!C9*'Valori input_3_20'!$B$19 -> 0.037519041 | E8: ='Valori input_3_20'!D9*'Valori input_3_20'!$B$19 -> 0.13395006 | F8: ='Valori input_3_20'!E9*'Valori input_3_20'!$B$19 -> 0.12820214 | G8: ='Valori input_3_20'!F9*'Valori input_3_20'!$B$19 -> 0.018557256 | H8: ='Valori input_3_20'!G9*'Valori input_3_20'!$B$19 -> 0.031839453 | I8: ='Valori input_3_20'!H9*'Valori input_3_20'!$B$19 -> 0.1033827 | J8: ='Valori input_3_20'!I9*'Valori input_3_20'!$B$19 -> 0.039661865 | ... U8: ='Valori input_3_20'!T9*'Valori input_3_20'!$B$19 -> 0.03474521
B9: 25 | C9: ='Valori input_3_20'!B10*'Valori input_3_20'!$B$19 -> 0.072071503 | D9: ='Valori input_3_20'!C10*'Valori input_3_20'!$B$19 -> 0.050450361 | E9: ='Valori input_3_20'!D10*'Valori input_3_20'!$B$19 -> 0.16048941 | F9: ='Valori input_3_20'!E10*'Valori input_3_20'!$B$19 -> 0.16281355 | G9: ='Valori input_3_20'!F10*'Valori input_3_20'!$B$19 -> 0.025143425 | H9: ='Valori input_3_20'!G10*'Valori input_3_20'!$B$19 -> 0.041522678 | I9: ='Valori input_3_20'!H10*'Valori input_3_20'!$B$19 -> 0.12935922 | J9: ='Valori input_3_20'!I10*'Valori input_3_20'!$B$19 -> 0.053601311 | ... U9: ='Valori input_3_20'!T10*'Valori input_3_20'!$B$19 -> 0.058534197
B10: 30 | C10: ='Valori input_3_20'!B11*'Valori input_3_20'!$B$19 -> 0.082035815 | D10: ='Valori input_3_20'!C11*'Valori input_3_20'!$B$19 -> 0.06060004 | E10: ='Valori input_3_20'!D11*'Valori input_3_20'!$B$19 -> 0.19649856 | F10: ='Valori input_3_20'!E11*'Valori input_3_20'!$B$19 -> 0.19849096 | G10: ='Valori input_3_20'!F11*'Valori input_3_20'!$B$19 -> 0.030839012 | H10: ='Valori input_3_20'!G11*'Valori input_3_20'!$B$19 -> 0.04850612 | I10: ='Valori input_3_20'!H11*'Valori input_3_20'!$B$19 -> 0.16158127 | J10: ='Valori input_3_20'!I11*'Valori input_3_20'!$B$19 -> 0.065298025 | ... U10: ='Valori input_3_20'!T11*'Valori input_3_20'!$B$19 -> 0.078465197
B11: 35 | C11: ='Valori input_3_20'!B12*'Valori input_3_20'!$B$19 -> 0.0913211 | D11: ='Valori input_3_20'!C12*'Valori input_3_20'!$B$19 -> 0.072372343 | E11: ='Valori input_3_20'!D12*'Valori input_3_20'!$B$19 -> 0.24697105 | F11: ='Valori input_3_20'!E12*'Valori input_3_20'!$B$19 -> 0.2439455 | G11: ='Valori input_3_20'!F12*'Valori input_3_20'!$B$19 -> 0.036886689 | H11: ='Valori input_3_20'!G12*'Valori input_3_20'!$B$19 -> 0.055795536 | I11: ='Valori input_3_20'!H12*'Valori input_3_20'!$B$19 -> 0.20304949 | J11: ='Valori input_3_20'!I12*'Valori input_3_20'!$B$19 -> 0.079289226 | ... U11: ='Valori input_3_20'!T12*'Valori input_3_20'!$B$19 -> 0.10127512
B12: 40 | C12: ='Valori input_3_20'!B13*'Valori input_3_20'!$B$19 -> 0.10096959 | D12: ='Valori input_3_20'!C13*'Valori input_3_20'!$B$19 -> 0.084707597 | E12: ='Valori input_3_20'!D13*'Valori input_3_20'!$B$19 -> 0.28886899 | F12: ='Valori input_3_20'!E13*'Valori input_3_20'!$B$19 -> 0.28352044 | G12: ='Valori input_3_20'!F13*'Valori input_3_20'!$B$19 -> 0.043100056 | H12: ='Valori input_3_20'!G13*'Valori input_3_20'!$B$19 -> 0.063588913 | I12: ='Valori input_3_20'!H13*'Valori input_3_20'!$B$19 -> 0.23825474 | J12: ='Valori input_3_20'!I13*'Valori input_3_20'!$B$19 -> 0.094056758 | ... U12: ='Valori input_3_20'!T13*'Valori input_3_20'!$B$19 -> 0.12474941
B13: 45 | C13: ='Valori input_3_20'!B14*'Valori input_3_20'!$B$19 -> 0.11361842 | D13: ='Valori input_3_20'!C14*'Valori input_3_20'!$B$19 -> 0.10138089 | E13: ='Valori input_3_20'!D14*'Valori input_3_20'!$B$19 -> 0.33034915 | F13: ='Valori input_3_20'!E14*'Valori input_3_20'!$B$19 -> 0.32586029 | G13: ='Valori input_3_20'!F14*'Valori input_3_20'!$B$19 -> 0.049996893 | H13: ='Valori input_3_20'!G14*'Valori input_3_20'!$B$19 -> 0.07338013 | I13: ='Valori input_3_20'!H14*'Valori input_3_20'!$B$19 -> 0.27516966 | J13: ='Valori input_3_20'!I14*'Valori input_3_20'!$B$19 -> 0.11222289 | ... U13: ='Valori input_3_20'!T14*'Valori input_3_20'!$B$19 -> 0.15781622
B14: 50 | C14: ='Valori input_3_20'!B15*'Valori input_3_20'!$B$19 -> 0.13152576 | D14: ='Valori input_3_20'!C15*'Valori input_3_20'!$B$19 -> 0.12444533 | E14: ='Valori input_3_20'!D15*'Valori input_3_20'!$B$19 -> 0.37614642 | F14: ='Valori input_3_20'!E15*'Valori input_3_20'!$B$19 -> 0.37221426 | G14: ='Valori input_3_20'!F15*'Valori input_3_20'!$B$19 -> 0.057908581 | H14: ='Valori input_3_20'!G15*'Valori input_3_20'!$B$19 -> 0.084521238 | I14: ='Valori input_3_20'!H15*'Valori input_3_20'!$B$19 -> 0.31644598 | J14: ='Valori input_3_20'!I15*'Valori input_3_20'!$B$19 -> 0.13603036 | ... U14: ='Valori input_3_20'!T15*'Valori input_3_20'!$B$19 -> 0.20652478
A17: Xc | C17: 0.037040051 | D17: 0.026853511 | E17: 0.090100513 | F17: 0.085758627 | G17: 0.011518427 | H17: 0.02281781 | I17: 0.068597681 | J17: 0.027471227 | K17: 0.07274858 | L17: 0.025192804 | M17: 0.036271925 | N17: 0.012582288 | O17: 0.014097917 | P17: 0.012141568 | Q17: 0.021300799 | R17: 0.014056176 | S17: 0.01422368 | T17: 0.011816432 | U17: 0.023898569 | X17: pA | Y17: 12.282 | Z17: mbar
A18: Xa | C18: 0.0035395887 | D18: 0.0066011227 | E18: 0.015955039 | F18: 0.012376557 | G18: 0.00090919816 | H18: 0.0048499234 | I18: 0.010084724 | J18: 0.0054996254 | K18: 0.011812913 | L18: 0.003771444 | M18: 0.0025018558 | N18: 0.0029222153 | O18: 0.0043639918 | P18: 0.0028638755 | Q18: 0.0017552724 | R18: 0.0026460509 | S18: 0.00047442957 | T18: 0.0030690569 | U18: 0.0030733084 | X18: pC | Y18: 42.47 | Z18: mbar
A19: DeltaX | C19: 0.033500462 | D19: 0.020252388 | E19: 0.074145473 | F19: 0.073382071 | G19: 0.010609229 | H19: 0.017967886 | I19: 0.058512957 | J19: 0.021971602 | K19: 0.060935668 | L19: 0.02142136 | M19: 0.033770069 | N19: 0.0096600728 | O19: 0.009733925 | P19: 0.009277693 | Q19: 0.019545527 | R19: 0.011410125 | S19: 0.013749251 | T19: 0.0087473748 | U19: 0.020825261
A20: qst | C20: 48.723063 | D20: 48.773237 | E20: 48.754015 | F20: 48.730677 | G20: 48.658847 | H20: 48.787397 | I20: 48.72509 | J20: 48.747833 | K20: 48.739464 | L20: 48.717846 | M20: 48.674396 | N20: 48.793474 | O20: 48.827343 | P20: 48.793586 | Q20: 48.617344 | R20: 48.777953 | S20: 48.502503 | T20: 48.795953 | U20: 48.656341
A21: Qu | C21: 90.60478 | D21: 54.83067 | E21: 200.65998 | F21: 198.49892 | G21: 28.655722 | H21: 48.659806 | I21: 158.25974 | J21: 59.454231 | K21: 164.86105 | L21: 57.929645 | M21: 91.242727 | N21: 26.164225 | O21: 26.382553 | P21: 25.12861 | Q21: 52.747799 | R21: 30.894397 | S21: 37.017656 | T21: 23.693394 | U21: 56.246516
A22: W0_20 | C22: 0.17241613 | D22: 0.77706756 | E22: 0.9231419 | F22: 0.79361236 | G22: 0.10097575 | H22: 0.19361892 | I22: 0.76698835 | J22: 0.6025782 | K22: 0.79573197 | L22: 0.36761456 | M22: 0.19680565 | N22: 0.12533231 | O22: 0.1841376 | P22: 0.12826637 | Q22: 0.68964754 | R22: 0.10225147 | S22: 1.0749109 | T22: 0.18304261 | U22: 2.2080061
A23: E_20 | C23: 3542.7766 | D23: 588.14751 | E23: 1891.9609 | F23: 2183.3096 | G23: 2574.5514 | H23: 2035.9681 | I23: 1903.943 | J23: 942.55852 | K23: 1864.3857 | L23: 1561.6331 | M23: 3358.5221 | N23: 1705.5892 | O23: 1048.3549 | P23: 1605.3885 | Q23: 1185.8116 | R23: 2394.9391 | S23: 1039.7329 | T23: 1042.7821 | U23: 421.96568
A24: n_20 | C24: 1.5575798 | D24: 0.58564138 | E24: 0.93457482 | F24: 1.0517773 | G24: 1.3015207 | H24: 0.91539397 | I24: 0.98222193 | J24: 0.70453744 | K24: 0.94981516 | L24: 0.90002355 | M24: 1.5933859 | N24: 0.82626763 | O24: 0.63169534 | P24: 0.80307221 | Q24: 0.9091567 | R24: 1.0260638 | S24: 0.97480021 | T24: 0.67231391 | U24: 0.62803306

Sheet Valori output_4_20
B1: RH [%] | C1: CaCl_4 | D1: LiCl_7 | E1: ZnN_5 | F1: MgN_3 | G1: CaCl_5 | H1: MgN_4 | I1: ZnN_6 | J1: SrB_4 | K1: LiCl_8 | L1: CaCl_6 | M1: ZnN_7 | N1: KAlS_8 | O1: MgCl_10 | P1: MgCl_11 | Q1: AlS_3 | R1: AlS_4 | S1: MgS_3 | T1: CaCl_7 | U1: MgCl_12 | V1: AlS_5 | W1: ZnN_3 | X1: ZnN_4 | Y1: -
C2: ='Valori input_4_20'!B$1 -> S01 | D2: ='Valori input_4_20'!C$1 -> S02 | E2: ='Valori input_4_20'!D$1 -> S03 | F2: ='Valori input_4_20'!E$1 -> S04 | G2: ='Valori input_4_20'!F$1 -> S05 | H2: ='Valori input_4_20'!G$1 -> S06 | I2: ='Valori input_4_20'!H$1 -> S07 | J2: ='Valori input_4_20'!I$1 -> S08 | ... Y2: ='Valori input_4_20'!X$1 -> S23
B3: RH [%] | C3: dm [g] | D3: dm [g] | E3: dm [g] | F3: dm [g] | G3: dm [g] | H3: dm [g] | I3: dm [g] | J3: dm [g] | K3: dm [g] | L3: dm [g] | M3: dm [g] | N3: dm [g] | O3: dm [g] | P3: dm [g] | Q3: dm [g] | R3: dm [g] | S3: dm [g] | T3: dm [g] | U3: dm [g] | V3: dm [g] | W3: dm [g] | X3: dm [g] | Y3: dm [g]
B4: 0 | C4: ='Valori input_4_20'!B5*'Valori input_4_20'!$B$19 -> 0 | D4: ='Valori input_4_20'!C5*'Valori input_4_20'!$B$19 -> 0 | E4: ='Valori input_4_20'!D5*'Valori input_4_20'!$B$19 -> 0 | F4: ='Valori input_4_20'!E5*'Valori input_4_20'!$B$19 -> 0 | G4: ='Valori input_4_20'!F5*'Valori input_4_20'!$B$19 -> 0 | H4: ='Valori input_4_20'!G5*'Valori input_4_20'!$B$19 -> 0 | I4: ='Valori input_4_20'!H5*'Valori input_4_20'!$B$19 -> 0 | J4: ='Valori input_4_20'!I5*'Valori input_4_20'!$B$19 -> 0 | ... Y4: ='Valori input_4_20'!X5*'Valori input_4_20'!$B$19 -> 0
B5: 5 | C5: ='Valori input_4_20'!B6*'Valori input_4_20'!$B$19 -> 0.017200679 | D5: ='Valori input_4_20'!C6*'Valori input_4_20'!$B$19 -> 0.017521902 | E5: ='Valori input_4_20'!D6*'Valori input_4_20'!$B$19 -> 0.0089237538 | F5: ='Valori input_4_20'!E6*'Valori input_4_20'!$B$19 -> 0.0071172129 | G5: ='Valori input_4_20'!F6*'Valori input_4_20'!$B$19 -> 0.012321282 | H5: ='Valori input_4_20'!G6*'Valori input_4_20'!$B$19 -> 0.0083390042 | I5: ='Valori input_4_20'!H6*'Valori input_4_20'!$B$19 -> 0.0077161353 | J5: ='Valori input_4_20'!I6*'Valori input_4_20'!$B$19 -> 0.011952092 | ... Y5: ='Valori input_4_20'!X6*'Valori input_4_20'!$B$19 -> 0
B6: 10 | C6: ='Valori input_4_20'!B7*'Valori input_4_20'!$B$19 -> 0.024746698 | D6: ='Valori input_4_20'!C7*'Valori input_4_20'!$B$19 -> 0.040498384 | E6: ='Valori input_4_20'!D7*'Valori input_4_20'!$B$19 -> 0.026563732 | F6: ='Valori input_4_20'!E7*'Valori input_4_20'!$B$19 -> 0.01647698 | G6: ='Valori input_4_20'!F7*'Valori input_4_20'!$B$19 -> 0.020279052 | H6: ='Valori input_4_20'!G7*'Valori input_4_20'!$B$19 -> 0.017681457 | I6: ='Valori input_4_20'!H7*'Valori input_4_20'!$B$19 -> 0.019995177 | J6: ='Valori input_4_20'!I7*'Valori input_4_20'!$B$19 -> 0.026612663 | ... Y6: ='Valori input_4_20'!X7*'Valori input_4_20'!$B$19 -> 0
B7: 15 | C7: ='Valori input_4_20'!B8*'Valori input_4_20'!$B$19 -> 0.03217336 | D7: ='Valori input_4_20'!C8*'Valori input_4_20'!$B$19 -> 0.075280668 | E7: ='Valori input_4_20'!D8*'Valori input_4_20'!$B$19 -> 0.074025651 | F7: ='Valori input_4_20'!E8*'Valori input_4_20'!$B$19 -> 0.030174456 | G7: ='Valori input_4_20'!F8*'Valori input_4_20'!$B$19 -> 0.03401947 | H7: ='Valori input_4_20'!G8*'Valori input_4_20'!$B$19 -> 0.032398704 | I7: ='Valori input_4_20'!H8*'Valori input_4_20'!$B$19 -> 0.036540352 | J7: ='Valori input_4_20'!I8*'Valori input_4_20'!$B$19 -> 0.060108339 | ... Y7: ='Valori input_4_20'!X8*'Valori input_4_20'!$B$19 -> 0
B8: 20 | C8: ='Valori input_4_20'!B9*'Valori input_4_20'!$B$19 -> 0.038432974 | D8: ='Valori input_4_20'!C9*'Valori input_4_20'!$B$19 -> 0.10466441 | E8: ='Valori input_4_20'!D9*'Valori input_4_20'!$B$19 -> 0.09807828 | F8: ='Valori input_4_20'!E9*'Valori input_4_20'!$B$19 -> 0.041239827 | G8: ='Valori input_4_20'!F9*'Valori input_4_20'!$B$19 -> 0.048409772 | H8: ='Valori input_4_20'!G9*'Valori input_4_20'!$B$19 -> 0.046942942 | I8: ='Valori input_4_20'!H9*'Valori input_4_20'!$B$19 -> 0.046686328 | J8: ='Valori input_4_20'!I9*'Valori input_4_20'!$B$19 -> 0.078185568 | ... Y8: ='Valori input_4_20'!X9*'Valori input_4_20'!$B$19 -> 0
B9: 25 | C9: ='Valori input_4_20'!B10*'Valori input_4_20'!$B$19 -> 0.048909872 | D9: ='Valori input_4_20'!C10*'Valori input_4_20'!$B$19 -> 0.14275307 | E9: ='Valori input_4_20'!D10*'Valori input_4_20'!$B$19 -> 0.12003486 | F9: ='Valori input_4_20'!E10*'Valori input_4_20'!$B$19 -> 0.057843148 | G9: ='Valori input_4_20'!F10*'Valori input_4_20'!$B$19 -> 0.070426271 | H9: ='Valori input_4_20'!G10*'Valori input_4_20'!$B$19 -> 0.067427135 | I9: ='Valori input_4_20'!H10*'Valori input_4_20'!$B$19 -> 0.057592788 | J9: ='Valori input_4_20'!I10*'Valori input_4_20'!$B$19 -> 0.092560382 | ... Y9: ='Valori input_4_20'!X10*'Valori input_4_20'!$B$19 -> 0
B10: 30 | C10: ='Valori input_4_20'!B11*'Valori input_4_20'!$B$19 -> 0.06092515 | D10: ='Valori input_4_20'!C11*'Valori input_4_20'!$B$19 -> 0.17815179 | E10: ='Valori input_4_20'!D11*'Valori input_4_20'!$B$19 -> 0.14074627 | F10: ='Valori input_4_20'!E11*'Valori input_4_20'!$B$19 -> 0.072983018 | G10: ='Valori input_4_20'!F11*'Valori input_4_20'!$B$19 -> 0.0925754 | H10: ='Valori input_4_20'!G11*'Valori input_4_20'!$B$19 -> 0.085385405 | I10: ='Valori input_4_20'!H11*'Valori input_4_20'!$B$19 -> 0.067683119 | J10: ='Valori input_4_20'!I11*'Valori input_4_20'!$B$19 -> 0.1017046 | ... Y10: ='Valori input_4_20'!X11*'Valori input_4_20'!$B$19 -> 0
B11: 35 | C11: ='Valori input_4_20'!B12*'Valori input_4_20'!$B$19 -> 0.076587449 | D11: ='Valori input_4_20'!C12*'Valori input_4_20'!$B$19 -> 0.22544972 | E11: ='Valori input_4_20'!D12*'Valori input_4_20'!$B$19 -> 0.1618935 | F11: ='Valori input_4_20'!E12*'Valori input_4_20'!$B$19 -> 0.088986218 | G11: ='Valori input_4_20'!F12*'Valori input_4_20'!$B$19 -> 0.12070612 | H11: ='Valori input_4_20'!G12*'Valori input_4_20'!$B$19 -> 0.10408184 | I11: ='Valori input_4_20'!H12*'Valori input_4_20'!$B$19 -> 0.077996031 | J11: ='Valori input_4_20'!I12*'Valori input_4_20'!$B$19 -> 0.10956913 | ... Y11: ='Valori input_4_20'!X12*'Valori input_4_20'!$B$19 -> 0
B12: 40 | C12: ='Valori input_4_20'!B13*'Valori input_4_20'!$B$19 -> 0.092766962 | D12: ='Valori input_4_20'!C13*'Valori input_4_20'!$B$19 -> 0.26846992 | E12: ='Valori input_4_20'!D13*'Valori input_4_20'!$B$19 -> 0.18299921 | F12: ='Valori input_4_20'!E13*'Valori input_4_20'!$B$19 -> 0.10255735 | G12: ='Valori input_4_20'!F13*'Valori input_4_20'!$B$19 -> 0.15349214 | H12: ='Valori input_4_20'!G13*'Valori input_4_20'!$B$19 -> 0.12034463 | I12: ='Valori input_4_20'!H13*'Valori input_4_20'!$B$19 -> 0.088067813 | J12: ='Valori input_4_20'!I13*'Valori input_4_20'!$B$19 -> 0.11706093 | ... Y12: ='Valori input_4_20'!X13*'Valori input_4_20'!$B$19 -> 0
B13: 45 | C13: ='Valori input_4_20'!B14*'Valori input_4_20'!$B$19 -> 0.11301788 | D13: ='Valori input_4_20'!C14*'Valori input_4_20'!$B$19 -> 0.31007042 | E13: ='Valori input_4_20'!D14*'Valori input_4_20'!$B$19 -> 0.20690657 | F13: ='Valori input_4_20'!E14*'Valori input_4_20'!$B$19 -> 0.1163917 | G13: ='Valori input_4_20'!F14*'Valori input_4_20'!$B$19 -> 0.19564179 | H13: ='Valori input_4_20'!G14*'Valori input_4_20'!$B$19 -> 0.13735712 | I13: ='Valori input_4_20'!H14*'Valori input_4_20'!$B$19 -> 0.099345241 | J13: ='Valori input_4_20'!I14*'Valori input_4_20'!$B$19 -> 0.12714939 | ... Y13: ='Valori input_4_20'!X14*'Valori input_4_20'!$B$19 -> 0
B14: 50 | C14: ='Valori input_4_20'!B15*'Valori input_4_20'!$B$19 -> 0.14233993 | D14: ='Valori input_4_20'!C15*'Valori input_4_20'!$B$19 -> 0.3539499 | E14: ='Valori input_4_20'!D15*'Valori input_4_20'!$B$19 -> 0.23344955 | F14: ='Valori input_4_20'!E15*'Valori input_4_20'!$B$19 -> 0.13105779 | G14: ='Valori input_4_20'!F15*'Valori input_4_20'!$B$19 -> 0.24978116 | H14: ='Valori input_4_20'!G15*'Valori input_4_20'!$B$19 -> 0.15543073 | I14: ='Valori input_4_20'!H15*'Valori input_4_20'!$B$19 -> 0.11164283 | J14: ='Valori input_4_20'!I15*'Valori input_4_20'!$B$19 -> 0.14444389 | ... Y14: ='Valori input_4_20'!X15*'Valori input_4_20'!$B$19 -> 0
A17: Xc | C17: 0.029003521 | D17: 0.070412694 | E17: 0.062646933 | F17: 0.028659165 | G17: 0.032009859 | H17: 0.031850375 | I17: 0.032879974 | J17: 0.054062513 | K17: 0.11780599 | L17: 0.054290749 | M17: 0.019292164 | N17: 0.016438452 | O17: 0.03254408 | P17: 0.023120904 | Q17: 0.021023247 | R17: 0.0057104011 | S17: 0.015755901 | T17: 0.026219002 | U17: 0.029066549 | V17: 0.0050738391 | W17: 0.015907372 | X17: 0.041319573 | AA17: pA | AB17: 12.282 | AC17: mbar
A18: Xa | C18: 0.0083504529 | D18: 0.0083980825 | E18: 0.0057890535 | F18: 0.0027802687 | G18: 0.0053501513 | H18: 0.0026040056 | I18: 0.0055373886 | J18: 0.004696978 | K18: 0.014178727 | L18: 0.0096423482 | M18: 0.0036797725 | N18: 0.0043829959 | O18: 0.011028216 | P18: 0.00043024559 | Q18: 0.0063289382 | R18: 0.0011511906 | S18: 0.0033198639 | T18: 0.0082006588 | U18: 0.0076769668 | V18: 0.00062267168 | W18: 0.0029402619 | X18: 0.0045963485 | AA18: pC | AB18: 42.47 | AC18: mbar
A19: DeltaX | C19: 0.020653068 | D19: 0.062014612 | E19: 0.056857879 | F19: 0.025878896 | G19: 0.026659708 | H19: 0.029246369 | I19: 0.027342585 | J19: 0.049365535 | K19: 0.10362727 | L19: 0.044648401 | M19: 0.015612392 | N19: 0.012055456 | O19: 0.021515864 | P19: 0.022690658 | Q19: 0.014694309 | R19: 0.0045592105 | S19: 0.012436037 | T19: 0.018018343 | U19: 0.021389583 | V19: 0.0044511674 | W19: 0.01296711 | X19: 0.036723225
A20: qst | C20: 48.78063 | D20: 48.694958 | E20: 48.710723 | F20: 48.685964 | G20: 48.688558 | H20: 48.662997 | I20: 48.779201 | J20: 48.765761 | K20: 48.710035 | L20: 48.709453 | M20: 48.780314 | N20: 48.83358 | O20: 48.871164 | P20: 48.473567 | Q20: 48.841347 | R20: 48.746097 | S20: 48.798102 | T20: 48.813574 | U20: 48.802194 | V20: 48.69174 | W20: 48.7835 | X20: 48.743174
A21: Qu | C21: 55.923933 | D21: 167.62692 | E21: 153.73791 | F21: 69.938329 | G21: 72.05233 | H21: 79.001721 | I21: 74.035497 | J21: 133.63019 | K21: 280.1936 | L21: 120.72157 | M21: 42.274624 | N21: 32.678938 | O21: 58.368322 | P21: 61.054519 | Q21: 39.838459 | R21: 12.336593 | S21: 33.686095 | T21: 48.822632 | U21: 57.943856 | V21: 12.030812 | W21: 35.114128 | X21: 99.362007
A22: W0_20 | C22: 3.1913197 | D22: 0.8395029 | E22: 0.32345214 | F22: 0.23754416 | G22: 4.9982546 | H22: 0.27858662 | I22: 0.18183467 | J22: 0.15639152 | K22: 1.0261662 | L22: 3.4411833 | M22: 0.13876978 | N22: 0.10268613 | O22: 0.18583537 | P22: 0.7358081 | Q22: 0.16045271 | R22: 0.1410132 | S22: 0.10451139 | T22: 0.68297275 | U22: 0.39421853 | V22: 0.072779254 | W22: 0.099919017 | X22: 0.18693809
A23: E_20 | C23: 92.674091 | D23: 1952.9132 | E23: 3360.9188 | F23: 2564.2676 | G23: 194.45994 | H23: 2562.8017 | I23: 2985.6141 | J23: 4532.0131 | K23: 2381.1834 | L23: 410.37309 | M23: 2405.6088 | N23: 2406.0318 | O23: 2356.9296 | P23: 1780.7015 | Q23: 1881.3366 | R23: 843.23891 | S23: 2482.6245 | T23: 465.3199 | U23: 1172.0727 | V23: 1712.1306 | W23: 2679.4736 | X23: 3555.2183
A24: n_20 | C24: 0.39483641 | D24: 1.0409402 | E24: 1.5063053 | F24: 1.2492045 | G24: 0.50948652 | H24: 1.2898711 | I24: 1.1993143 | J24: 2.0062789 | K24: 1.146299 | L24: 0.58509612 | M24: 1.0243645 | N24: 0.91280143 | O24: 0.81180268 | P24: 1.2873646 | Q24: 0.77996895 | R24: 0.68070379 | S24: 1.0090841 | T24: 0.51239074 | U24: 0.69319075 | V24: 0.97614777 | W24: 1.0950545 | X24: 1.5091067

Sheet Valori output_5_20
B1: RH [%] | C1: LiCl_9 | D1: LiCl_10 | E1: LiCl_11 | F1: LiCl_12 | G1: SrB_5 | H1: CuS_3 | I1: LiCl_13 | J1: LiCl_14 | K1: CaCl_8 | L1: CaCl_9 | M1: MgCl_13 | N1: MgCl_14 | O1: MgCl_15 | P1: CaCl_10 | Q1: ZnN_8 | R1: ZnN_9 | S1: MgCl_16 | T1: MgN_5 | U1: KAlS_9 | V1: ZnN_10 | W1: - | X1: - | Y1: -
C2: ='Valori input_5_20'!B$1 -> S01 | D2: ='Valori input_4_20'!C$1 -> S02 | E2: ='Valori input_4_20'!D$1 -> S03 | F2: ='Valori input_4_20'!E$1 -> S04 | G2: ='Valori input_4_20'!F$1 -> S05 | H2: ='Valori input_4_20'!G$1 -> S06 | I2: ='Valori input_4_20'!H$1 -> S07 | J2: ='Valori input_4_20'!I$1 -> S08 | K2: ='Valori input_4_20'!J$1 -> S09 | ... Y2: ='Valori input_4_20'!X$1 -> S23
B3: RH [%] | C3: dm [g] | D3: dm [g] | E3: dm [g] | F3: dm [g] | G3: dm [g] | H3: dm [g] | I3: dm [g] | J3: dm [g] | K3: dm [g] | L3: dm [g] | M3: dm [g] | N3: dm [g] | O3: dm [g] | P3: dm [g] | Q3: dm [g] | R3: dm [g] | S3: dm [g] | T3: dm [g] | U3: dm [g] | V3: dm [g] | W3: dm [g] | X3: dm [g] | Y3: dm [g]
B4: 0 | C4: ='Valori input_5_20'!B5*'Valori input_5_20'!$B$19 -> 0 | D4: ='Valori input_5_20'!C5*'Valori input_5_20'!$B$19 -> 0 | E4: ='Valori input_5_20'!D5*'Valori input_5_20'!$B$19 -> 0 | F4: ='Valori input_5_20'!E5*'Valori input_5_20'!$B$19 -> 0 | G4: ='Valori input_5_20'!F5*'Valori input_5_20'!$B$19 -> 0 | H4: ='Valori input_5_20'!G5*'Valori input_5_20'!$B$19 -> 0 | I4: ='Valori input_5_20'!H5*'Valori input_5_20'!$B$19 -> 0 | J4: ='Valori input_5_20'!I5*'Valori input_5_20'!$B$19 -> 0 | ... Y4: ='Valori input_5_20'!X5*'Valori input_5_20'!$B$19 -> 0
B5: 5 | C5: ='Valori input_5_20'!B6*'Valori input_5_20'!$B$19 -> 0.0383134 | D5: ='Valori input_5_20'!C6*'Valori input_5_20'!$B$19 -> 0.048975385 | E5: ='Valori input_5_20'!D6*'Valori input_5_20'!$B$19 -> 0.026373399 | F5: ='Valori input_5_20'!E6*'Valori input_5_20'!$B$19 -> 0.022937314 | G5: ='Valori input_5_20'!F6*'Valori input_5_20'!$B$19 -> 0.0099700897 | H5: ='Valori input_5_20'!G6*'Valori input_5_20'!$B$19 -> 0.00021972287 | I5: ='Valori input_5_20'!H6*'Valori input_5_20'!$B$19 -> 0.026838721 | J5: ='Valori input_5_20'!I6*'Valori input_5_20'!$B$19 -> 0.044318358 | ... Y5: ='Valori input_5_20'!X6*'Valori input_5_20'!$B$19 -> 0
B6: 10 | C6: ='Valori input_5_20'!B7*'Valori input_5_20'!$B$19 -> 0.076766167 | D6: ='Valori input_5_20'!C7*'Valori input_5_20'!$B$19 -> 0.09460509 | E6: ='Valori input_5_20'!D7*'Valori input_5_20'!$B$19 -> 0.057992979 | F6: ='Valori input_5_20'!E7*'Valori input_5_20'!$B$19 -> 0.060546483 | G6: ='Valori input_5_20'!F7*'Valori input_5_20'!$B$19 -> 0.024721951 | H6: ='Valori input_5_20'!G7*'Valori input_5_20'!$B$19 -> 0.0015929908 | I6: ='Valori input_5_20'!H7*'Valori input_5_20'!$B$19 -> 0.066131537 | J6: ='Valori input_5_20'!I7*'Valori input_5_20'!$B$19 -> 0.088527903 | ... Y6: ='Valori input_5_20'!X7*'Valori input_5_20'!$B$19 -> 0
B7: 15 | C7: ='Valori input_5_20'!B8*'Valori input_5_20'!$B$19 -> 0.19269461 | D7: ='Valori input_5_20'!C8*'Valori input_5_20'!$B$19 -> 0.24958179 | E7: ='Valori input_5_20'!D8*'Valori input_5_20'!$B$19 -> 0.12983329 | F7: ='Valori input_5_20'!E8*'Valori input_5_20'!$B$19 -> 0.12969279 | G7: ='Valori input_5_20'!F8*'Valori input_5_20'!$B$19 -> 0.045755936 | H7: ='Valori input_5_20'!G8*'Valori input_5_20'!$B$19 -> 0.0029250608 | I7: ='Valori input_5_20'!H8*'Valori input_5_20'!$B$19 -> 0.14428171 | J7: ='Valori input_5_20'!I8*'Valori input_5_20'!$B$19 -> 0.23051453 | ... Y7: ='Valori input_5_20'!X8*'Valori input_5_20'!$B$19 -> 0
B8: 20 | C8: ='Valori input_5_20'!B9*'Valori input_5_20'!$B$19 -> 0.24030762 | D8: ='Valori input_5_20'!C9*'Valori input_5_20'!$B$19 -> 0.30639861 | E8: ='Valori input_5_20'!D9*'Valori input_5_20'!$B$19 -> 0.16581821 | F8: ='Valori input_5_20'!E9*'Valori input_5_20'!$B$19 -> 0.16472067 | G8: ='Valori input_5_20'!F9*'Valori input_5_20'!$B$19 -> 0.058020114 | H8: ='Valori input_5_20'!G9*'Valori input_5_20'!$B$19 -> 0.0039962098 | I8: ='Valori input_5_20'!H9*'Valori input_5_20'!$B$19 -> 0.18334228 | J8: ='Valori input_5_20'!I9*'Valori input_5_20'!$B$19 -> 0.28313384 | ... Y8: ='Valori input_5_20'!X9*'Valori input_5_20'!$B$19 -> 0
B9: 25 | C9: ='Valori input_5_20'!B10*'Valori input_5_20'!$B$19 -> 0.29667545 | D9: ='Valori input_5_20'!C10*'Valori input_5_20'!$B$19 -> 0.36993667 | E9: ='Valori input_5_20'!D10*'Valori input_5_20'!$B$19 -> 0.21052086 | F9: ='Valori input_5_20'!E10*'Valori input_5_20'!$B$19 -> 0.20152737 | G9: ='Valori input_5_20'!F10*'Valori input_5_20'!$B$19 -> 0.070187496 | H9: ='Valori input_5_20'!G10*'Valori input_5_20'!$B$19 -> 0.0051497549 | I9: ='Valori input_5_20'!H10*'Valori input_5_20'!$B$19 -> 0.22561073 | J9: ='Valori input_5_20'!I10*'Valori input_5_20'!$B$19 -> 0.3456863 | ... Y9: ='Valori input_5_20'!X10*'Valori input_5_20'!$B$19 -> 0
B10: 30 | C10: ='Valori input_5_20'!B11*'Valori input_5_20'!$B$19 -> 0.3536641 | D10: ='Valori input_5_20'!C11*'Valori input_5_20'!$B$19 -> 0.43347473 | E10: ='Valori input_5_20'!D11*'Valori input_5_20'!$B$19 -> 0.25939455 | F10: ='Valori input_5_20'!E11*'Valori input_5_20'!$B$19 -> 0.2430419 | G10: ='Valori input_5_20'!F11*'Valori input_5_20'!$B$19 -> 0.081686978 | H10: ='Valori input_5_20'!G11*'Valori input_5_20'!$B$19 -> 0.0063307653 | I10: ='Valori input_5_20'!H11*'Valori input_5_20'!$B$19 -> 0.27210312 | J10: ='Valori input_5_20'!I11*'Valori input_5_20'!$B$19 -> 0.40705736 | ... Y10: ='Valori input_5_20'!X11*'Valori input_5_20'!$B$19 -> 0
B11: 35 | C11: ='Valori input_5_20'!B12*'Valori input_5_20'!$B$19 -> 0.41791253 | D11: ='Valori input_5_20'!C12*'Valori input_5_20'!$B$19 -> 0.50917075 | E11: ='Valori input_5_20'!D12*'Valori input_5_20'!$B$19 -> 0.31515952 | F11: ='Valori input_5_20'!E12*'Valori input_5_20'!$B$19 -> 0.30381575 | G11: ='Valori input_5_20'!F12*'Valori input_5_20'!$B$19 -> 0.09318646 | H11: ='Valori input_5_20'!G12*'Valori input_5_20'!$B$19 -> 0.0076491026 | I11: ='Valori input_5_20'!H12*'Valori input_5_20'!$B$19 -> 0.33733471 | J11: ='Valori input_5_20'!I12*'Valori input_5_20'!$B$19 -> 0.47358931 | ... Y11: ='Valori input_5_20'!X12*'Valori input_5_20'!$B$19 -> 0
B12: 40 | C12: ='Valori input_5_20'!B13*'Valori input_5_20'!$B$19 -> 0.47727042 | D12: ='Valori input_5_20'!C13*'Valori input_5_20'!$B$19 -> 0.58128211 | E12: ='Valori input_5_20'!D13*'Valori input_5_20'!$B$19 -> 0.36681822 | F12: ='Valori input_5_20'!E13*'Valori input_5_20'!$B$19 -> 0.36250318 | G12: ='Valori input_5_20'!F13*'Valori input_5_20'!$B$19 -> 0.10519897 | H12: ='Valori input_5_20'!G13*'Valori input_5_20'!$B$19 -> 0.0089262418 | I12: ='Valori input_5_20'!H13*'Valori input_5_20'!$B$19 -> 0.40091156 | J12: ='Valori input_5_20'!I13*'Valori input_5_20'!$B$19 -> 0.5351469 | ... Y12: ='Valori input_5_20'!X13*'Valori input_5_20'!$B$19 -> 0
B13: 45 | C13: ='Valori input_5_20'!B14*'Valori input_5_20'!$B$19 -> 0.53705909 | D13: ='Valori input_5_20'!C14*'Valori input_5_20'!$B$19 -> 0.6497192 | E13: ='Valori input_5_20'!D14*'Valori input_5_20'!$B$19 -> 0.41535512 | F13: ='Valori input_5_20'!E14*'Valori input_5_20'!$B$19 -> 0.41264428 | G13: ='Valori input_5_20'!F14*'Valori input_5_20'!$B$19 -> 0.1196798 | H13: ='Valori input_5_20'!G14*'Valori input_5_20'!$B$19 -> 0.011398124 | I13: ='Valori input_5_20'!H14*'Valori input_5_20'!$B$19 -> 0.45448739 | J13: ='Valori input_5_20'!I14*'Valori input_5_20'!$B$19 -> 0.59664231 | ... Y13: ='Valori input_5_20'!X14*'Valori input_5_20'!$B$19 -> 0
B14: 50 | C14: ='Valori input_5_20'!B15*'Valori input_5_20'!$B$19 -> 0.60541253 | D14: ='Valori input_5_20'!C15*'Valori input_5_20'!$B$19 -> 0.72849205 | E14: ='Valori input_5_20'!D15*'Valori input_5_20'!$B$19 -> 0.47104237 | F14: ='Valori input_5_20'!E15*'Valori input_5_20'!$B$19 -> 0.46714547 | G14: ='Valori input_5_20'!F15*'Valori input_5_20'!$B$19 -> 0.13835193 | H14: ='Valori input_5_20'!G15*'Valori input_5_20'!$B$19 -> 0.015078482 | I14: ='Valori input_5_20'!H15*'Valori input_5_20'!$B$19 -> 0.51340485 | J14: ='Valori input_5_20'!I15*'Valori input_5_20'!$B$19 -> 0.66867713 | ... Y14: ='Valori input_5_20'!X15*'Valori input_5_20'!$B$19 -> 0
A17: Xc | C17: 0.16244925 | D17: 0.20656348 | E17: 0.11236328 | F17: 0.1097456 | G17: 0.040554589 | H17: 0.0024466387 | I17: 0.12261774 | J17: 0.19230695 | K17: 0.027593879 | L17: 0.046854981 | M17: 0.016302468 | N17: 0.031196417 | O17: 0.028911793 | P17: 0.021428657 | Q17: 0.0090075915 | R17: 0.045051287 | S17: 0.030164481 | T17: 0.020083218 | U17: 0.011659004 | V17: 0.018627448 | Y17: pA | Z17: 12.282 | AA17: mbar
A18: Xa | C18: 0.022035665 | D18: 0.028474749 | E18: 0.015224383 | F18: 0.017638197 | G18: 0.0082137527 | H18: 0.00055394666 | I18: 0.019029185 | J18: 0.024427627 | K18: 0.0039947037 | L18: 0.0066783516 | M18: 0.0034758675 | N18: 0.0087742773 | O18: 0.0076813353 | P18: 0.0047961547 | Q18: 0.0042515287 | R18: 0.006017365 | S18: 0.0072279159 | T18: 0.0052468082 | U18: 0.00307947 | V18: 0.0039355898 | Y18: pC | Z18: 42.47 | AA18: mbar
A19: DeltaX | C19: 0.14041359 | D19: 0.17808873 | E19: 0.097138899 | F19: 0.092107403 | G19: 0.032340836 | H19: 0.0018926921 | I19: 0.10358856 | J19: 0.16787932 | K19: 0.023599175 | L19: 0.040176629 | M19: 0.0128266 | N19: 0.02242214 | O19: 0.021230458 | P19: 0.016632502 | Q19: 0.0047560628 | R19: 0.039033922 | S19: 0.022936566 | T19: 0.01483641 | U19: 0.0085795336 | V19: 0.014691858
A20: qst | C20: 48.745216 | D20: 48.75483 | E20: 48.728704 | F20: 48.742452 | G20: 48.797029 | H20: 48.740714 | I20: 48.741235 | J20: 48.749427 | K20: 48.679287 | L20: 48.682012 | M20: 48.805959 | N20: 48.78337 | O20: 48.774742 | P20: 48.758958 | Q20: 48.891033 | R20: 48.752525 | S20: 48.759099 | T20: 48.825698 | U20: 48.790195 | V20: 48.779956
A21: Qu | C21: 379.93287 | D21: 481.96979 | E21: 262.75063 | F21: 249.21125 | G21: 87.601261 | H21: 5.1207973 | I21: 280.26835 | J21: 454.28924 | K21: 63.768582 | L21: 108.56948 | M21: 34.749626 | N21: 60.717598 | O21: 57.48044 | P21: 45.017124 | Q21: 12.907512 | R21: 105.63432 | S21: 62.079727 | T21: 40.210829 | U21: 23.236032 | V21: 39.781747
A22: W0_20 | C22: 0.98981938 | D22: 1.1238206 | E22: 0.91259198 | F22: 1.0784288 | G22: 0.24907246 | H22: 0.26535428 | I22: 1.1127322 | J22: 0.9807238 | K22: 1.7250716 | L22: 2.1974433 | M22: 0.096696853 | N22: 1.8910676 | O22: 1.6514348 | P22: 0.61043695 | Q22: 0.12684413 | R22: 0.23957087 | S22: 1.5902351 | T22: 0.13885223 | U22: 0.25520032 | V22: 0.18541764
A23: E_20 | C23: 2910.2968 | D23: 3115.4801 | E23: 2421.9879 | F23: 2022.9522 | G23: 2662.191 | H23: 165.72289 | I23: 2165.3022 | J23: 3274.8215 | K23: 515.84386 | L23: 659.4281 | M23: 2696.6578 | N23: 206.10882 | O23: 248.29102 | P23: 666.33738 | Q23: 460.61602 | R23: 3173.2747 | S23: 325.41823 | T23: 2218.8678 | U23: 720.0002 | V23: 1791.3658
A24: n_20 | C24: 1.2510726 | D24: 1.3017092 | E24: 1.1259017 | F24: 0.98770485 | G24: 1.0605479 | H24: 0.4626526 | I24: 1.0289609 | J24: 1.3749356 | K24: 0.64433033 | L24: 0.68835679 | M24: 1.0501092 | N24: 0.45251071 | O24: 0.47625254 | P24: 0.62078233 | Q24: 0.41988063 | R24: 1.3285006 | S24: 0.5170991 | T24: 0.88591182 | U24: 0.60268055 | V24: 0.86825643

Sheet Valori output_6_20
B1: RH [%] | C1: LiCl_15 | D1: CaCl_11 | E1: CaCl_12 | F1: ZnN_11 | G1: LiCl_16 | H1: LiCl_17 | I1: MgCl_17 | J1: CaCl_13 | K1: LiCl_18 | L1: LiCl_19 | M1: CaCl_14 | N1: ZnN_12 | O1: CaCl_15 | P1: KAlS_10 | Q1: ZnN_13 | R1: MgCl_18 | S1: MgS_4 | T1: MgCl_19 | U1: ZnN_14 | V1: ZnN_15 | W1: - | X1: - | Y1: -
C2: ='Valori input_6_20'!B$1 -> S01 | D2: ='Valori input_6_20'!C$1 -> S02 | E2: ='Valori input_6_20'!D$1 -> S03 | F2: ='Valori input_6_20'!E$1 -> S04 | G2: ='Valori input_6_20'!F$1 -> S05 | H2: ='Valori input_6_20'!G$1 -> S06 | I2: ='Valori input_6_20'!H$1 -> S07 | J2: ='Valori input_6_20'!I$1 -> S08 | ... Y2: ='Valori input_6_20'!X$1 -> S23
B3: RH [%] | C3: dm [g] | D3: dm [g] | E3: dm [g] | F3: dm [g] | G3: dm [g] | H3: dm [g] | I3: dm [g] | J3: dm [g] | K3: dm [g] | L3: dm [g] | M3: dm [g] | N3: dm [g] | O3: dm [g] | P3: dm [g] | Q3: dm [g] | R3: dm [g] | S3: dm [g] | T3: dm [g] | U3: dm [g] | V3: dm [g] | W3: dm [g] | X3: dm [g] | Y3: dm [g]
B4: 0 | C4: ='Valori input_6_20'!B5*'Valori input_6_20'!$B$19 -> 0 | D4: ='Valori input_6_20'!C5*'Valori input_6_20'!$B$19 -> 0 | E4: ='Valori input_6_20'!D5*'Valori input_6_20'!$B$19 -> 0 | F4: ='Valori input_6_20'!E5*'Valori input_6_20'!$B$19 -> 0 | G4: ='Valori input_6_20'!F5*'Valori input_6_20'!$B$19 -> 0 | H4: ='Valori input_6_20'!G5*'Valori input_6_20'!$B$19 -> 0 | I4: ='Valori input_6_20'!H5*'Valori input_6_20'!$B$19 -> 0 | J4: ='Valori input_6_20'!I5*'Valori input_6_20'!$B$19 -> 0 | ... Y4: ='Valori input_6_20'!X5*'Valori input_6_20'!$B$19 -> 0
B5: 5 | C5: ='Valori input_6_20'!B6*'Valori input_6_20'!$B$19 -> 0.04853389 | D5: ='Valori input_6_20'!C6*'Valori input_6_20'!$B$19 -> 0.0084885817 | E5: ='Valori input_6_20'!D6*'Valori input_6_20'!$B$19 -> 0.012081547 | F5: ='Valori input_6_20'!E6*'Valori input_6_20'!$B$19 -> 0.0066535278 | G5: ='Valori input_6_20'!F6*'Valori input_6_20'!$B$19 -> 0.059259699 | H5: ='Valori input_6_20'!G6*'Valori input_6_20'!$B$19 -> 0.051916933 | I5: ='Valori input_6_20'!H6*'Valori input_6_20'!$B$19 -> 0.0076982176 | J5: ='Valori input_6_20'!I6*'Valori input_6_20'!$B$19 -> 0.011785558 | ... Y5: ='Valori input_6_20'!X6*'Valori input_6_20'!$B$19 -> 0
B6: 10 | C6: ='Valori input_6_20'!B7*'Valori input_6_20'!$B$19 -> 0.07753105 | D6: ='Valori input_6_20'!C7*'Valori input_6_20'!$B$19 -> 0.016388722 | E6: ='Valori input_6_20'!D7*'Valori input_6_20'!$B$19 -> 0.029011023 | F6: ='Valori input_6_20'!E7*'Valori input_6_20'!$B$19 -> 0.022782814 | G6: ='Valori input_6_20'!F7*'Valori input_6_20'!$B$19 -> 0.088108514 | H6: ='Valori input_6_20'!G7*'Valori input_6_20'!$B$19 -> 0.085479899 | I6: ='Valori input_6_20'!H7*'Valori input_6_20'!$B$19 -> 0.013652428 | J6: ='Valori input_6_20'!I7*'Valori input_6_20'!$B$19 -> 0.026772133 | ... Y6: ='Valori input_6_20'!X7*'Valori input_6_20'!$B$19 -> 0
B7: 15 | C7: ='Valori input_6_20'!B8*'Valori input_6_20'!$B$19 -> 0.2196599 | D7: ='Valori input_6_20'!C8*'Valori input_6_20'!$B$19 -> 0.032702324 | E7: ='Valori input_6_20'!D8*'Valori input_6_20'!$B$19 -> 0.067080016 | F7: ='Valori input_6_20'!E8*'Valori input_6_20'!$B$19 -> 0.035270004 | G7: ='Valori input_6_20'!F8*'Valori input_6_20'!$B$19 -> 0.26468146 | H7: ='Valori input_6_20'!G8*'Valori input_6_20'!$B$19 -> 0.24773695 | I7: ='Valori input_6_20'!H8*'Valori input_6_20'!$B$19 -> 0.027281807 | J7: ='Valori input_6_20'!I8*'Valori input_6_20'!$B$19 -> 0.062737265 | ... Y7: ='Valori input_6_20'!X8*'Valori input_6_20'!$B$19 -> 0
B8: 20 | C8: ='Valori input_6_20'!B9*'Valori input_6_20'!$B$19 -> 0.26531974 | D8: ='Valori input_6_20'!C9*'Valori input_6_20'!$B$19 -> 0.047263121 | E8: ='Valori input_6_20'!D9*'Valori input_6_20'!$B$19 -> 0.10026281 | F8: ='Valori input_6_20'!E9*'Valori input_6_20'!$B$19 -> 0.044130863 | G8: ='Valori input_6_20'!F9*'Valori input_6_20'!$B$19 -> 0.31488512 | H8: ='Valori input_6_20'!G9*'Valori input_6_20'!$B$19 -> 0.29973709 | I8: ='Valori input_6_20'!H9*'Valori input_6_20'!$B$19 -> 0.036754763 | J8: ='Valori input_6_20'!I9*'Valori input_6_20'!$B$19 -> 0.09401992 | ... Y8: ='Valori input_6_20'!X9*'Valori input_6_20'!$B$19 -> 0
B9: 25 | C9: ='Valori input_6_20'!B10*'Valori input_6_20'!$B$19 -> 0.3140076 | D9: ='Valori input_6_20'!C10*'Valori input_6_20'!$B$19 -> 0.067282652 | E9: ='Valori input_6_20'!D10*'Valori input_6_20'!$B$19 -> 0.13229741 | F9: ='Valori input_6_20'!E10*'Valori input_6_20'!$B$19 -> 0.053496255 | G9: ='Valori input_6_20'!F10*'Valori input_6_20'!$B$19 -> 0.3648515 | H9: ='Valori input_6_20'!G10*'Valori input_6_20'!$B$19 -> 0.3522697 | I9: ='Valori input_6_20'!H10*'Valori input_6_20'!$B$19 -> 0.052281807 | J9: ='Valori input_6_20'!I10*'Valori input_6_20'!$B$19 -> 0.12858296 | ... Y9: ='Valori input_6_20'!X10*'Valori input_6_20'!$B$19 -> 0
B10: 30 | C10: ='Valori input_6_20'!B11*'Valori input_6_20'!$B$19 -> 0.36533 | D10: ='Valori input_6_20'!C11*'Valori input_6_20'!$B$19 -> 0.090494792 | E10: ='Valori input_6_20'!D11*'Valori input_6_20'!$B$19 -> 0.15813176 | F10: ='Valori input_6_20'!E11*'Valori input_6_20'!$B$19 -> 0.063366181 | G10: ='Valori input_6_20'!F11*'Valori input_6_20'!$B$19 -> 0.41790248 | H10: ='Valori input_6_20'!G11*'Valori input_6_20'!$B$19 -> 0.4073316 | I10: ='Valori input_6_20'!H11*'Valori input_6_20'!$B$19 -> 0.074062692 | J10: ='Valori input_6_20'!I11*'Valori input_6_20'!$B$19 -> 0.16755069 | ... Y10: ='Valori input_6_20'!X11*'Valori input_6_20'!$B$19 -> 0
